Workbook

Sheet Regular Season Standings
B2: Seed | C2: Pod A | D2: Record | E2: Cup Diff | F2: Shooting % | H2: Seed | I2: Pod E | J2: Record | K2: Cup Diff | L2: Shooting %
B3: 1 | C3: Pierre/Anson | D3: 3-0 | E3: +7 | F3: {=xlookup("Anson/Pierre",'Team Stats'!B:B,'Team Stats'!C:C)} -> 0.28494624 | H3: 1 | I3: Bonn/Ale | J3: 1-2 | K3: +0 | L3: {=xlookup("Alejandro/Bonn",'Team Stats'!B:B,'Team Stats'!C:C)} -> 0.22413793
B4: 2 | C4: Giacomo/Skatz | D4: 1-2 | E4: +0 | F4: {=xlookup("Giacomo/Skatz",'Team Stats'!B:B,'Team Stats'!C:C)} -> 0.20529801 | H4: 2 | I4: Curtis/Ronilo | J4: 1-2 | K4: -6 | L4: {=xlookup("Curtis/Ronilo",'Team Stats'!B:B,'Team Stats'!C:C)} -> 0.16528926
B5: 3 | C5: Toban/Homo | D5: 2-1 | E5: -3 | F5: {=xlookup("Toban/Homo",'Team Stats'!B:B,'Team Stats'!C:C)} -> 0.23076923 | H5: 3 | I5: Bash/Grant Mullen | J5: 2-1 | K5: +3 | L5: {=xlookup("Bash/Grant Mullen",'Team Stats'!B:B,'Team Stats'!C:C)} -> 0.17
B6: 4 | C6: Arturo/Griss | D6: 0-3 | E6: -4 | F6: {=xlookup("Arturo/Griss",'Team Stats'!B:B,'Team Stats'!C:C)} -> 0.21666667 | H6: 4 | I6: Shuford/JP | J6: 2-1 | K6: +3 | L6: {=xlookup("JP/Ford",'Team Stats'!B:B,'Team Stats'!C:C)} -> 0.24683544
C8: Pod B | I8: Pod F
B9: 1 | C9: Cam/Ham | D9: 2-1 | E9: +1 | F9: {=xlookup("Camden/Hamoui",'Team Stats'!B:B,'Team Stats'!C:C)} -> 0.17721519 | H9: 1 | I9: Naman/Liam | J9: 2-1 | K9: +1 | L9: {=xlookup("Naman/Liam",'Team Stats'!B:B,'Team Stats'!C:C)} -> 0.24503311
B10: 2 | C10: Wigs/Boggs | D10: 3-0 | E10: +5 | F10: {=xlookup("Wigs/Boggs",'Team Stats'!B:B,'Team Stats'!C:C)} -> 0.27722772 | H10: 2 | I10: Isaiah/Mike | J10: 1-2 | K10: +0 | L10: {=xlookup("Isaiah/Mike Miller",'Team Stats'!B:B,'Team Stats'!C:C)} -> 0.22368421
B11: 3 | C11: Bello/Keith | D11: 0-3 | E11: -6 | F11: {=xlookup("Bello/Keith",'Team Stats'!B:B,'Team Stats'!C:C)} -> 0.22222222 | H11: 3 | I11: Digs/Manndrew | J11: 0-3 | K11: -6 | L11: {=xlookup("Digs/Manndrew",'Team Stats'!B:B,'Team Stats'!C:C)} -> 0.20689655
B12: 4 | C12: Cestero/Messina | D12: 1-2 | E12: +0 | F12: {=xlookup("Cestero/Messina",'Team Stats'!B:B,'Team Stats'!C:C)} -> 0.26213592 | H12: 4 | I12: Reed/Pranav | J12: 3-0 | K12: +5 | L12: {=xlookup("Reed/Pranav",'Team Stats'!B:B,'Team Stats'!C:C)} -> 0.18139535
C14: Pod C | I14: Pod G
B15: 1 | C15: Everett/Hulu | D15: 3-0 | E15: +7 | F15: {=xlookup("Everett/Hulu",'Team Stats'!B:B,'Team Stats'!C:C)} -> 0.2027027 | H15: 1 | I15: Vish/Akash | J15: 1-2 | K15: -4 | L15: {=xlookup("Kavishka/Akash",'Team Stats'!B:B,'Team Stats'!C:C)} -> 0.24
B16: 2 | C16: Blume/Raza | D16: 2-1 | E16: +3 | F16: {=xlookup("Blume/Raza",'Team Stats'!B:B,'Team Stats'!C:C)} -> 0.33333333 | H16: 2 | I16: Brock/Vinny | J16: 2-1 | K16: +5 | L16: {=xlookup("Brock/Vinny",'Team Stats'!B:B,'Team Stats'!C:C)} -> 0.26515152
B17: 3 | C17: Plump/Voelker | D17: 1-2 | E17: -2 | F17: {=xlookup("Plump/Voelkbeezy",'Team Stats'!B:B,'Team Stats'!C:C)} -> 0.2 | H17: 3 | I17: Mati/Takoa | J17: 2-1 | K17: +1 | L17: {=xlookup("Mati/Takoa",'Team Stats'!B:B,'Team Stats'!C:C)} -> 0.26229508
B18: 4 | C18: PJ/Chrizz | D18: 0-3 | E18: -8 | F18: {=xlookup("PJ/Chris Connors",'Team Stats'!B:B,'Team Stats'!C:C)} -> 0.16901408 | H18: 4 | I18: Albright/Wilder | J18: 1-2 | K18: -2 | L18: {=xlookup("Albright/Wilder",'Team Stats'!B:B,'Team Stats'!C:C)} -> 0.23636364
C20: Pod D | I20: Pod H
B21: 1 | C21: Chuckdee/Sarch | D21: 2-1 | E21: +8 | F21: {=xlookup("Charlie/Sarchio",'Team Stats'!B:B,'Team Stats'!C:C)} -> 0.33636364 | H21: 1 | I21: Schreder/Matian | J21: 1-2 | K21: -1 | L21: {=xlookup("Schreder/Dylan and Matian",'Team Stats'!B:B,'Team Stats'!C:C)} -> 0.28723404
B22: 2 | C22: Brando/Heath | D22: 3-0 | E22: +8 | F22: {=xlookup("Brando/Heath",'Team Stats'!B:B,'Team Stats'!C:C)} -> 0.32857143 | H22: 2 | I22: Creamer/Hudson | J22: 2-1 | K22: +4 | L22: {=xlookup("Creamer/Hudson",'Team Stats'!B:B,'Team Stats'!C:C)} -> 0.2875
B23: 3 | C23: Creditor/King | D23: 0-3 | E23: -9 | F23: {=xlookup("Creditor/King",'Team Stats'!B:B,'Team Stats'!C:C)} -> 0.31343284 | H23: 3 | I23: Tolsma/Emilio | J23: 2-1 | K23: +0 | L23: {=xlookup("Emilio/Tolsma",'Team Stats'!B:B,'Team Stats'!C:C)} -> 0.23809524
B24: 4 | C24: Shawnak/Mackie | D24: 1-2 | E24: -7 | F24: {=xlookup("Shawnak/Mackie",'Team Stats'!B:B,'Team Stats'!C:C)} -> 0.29032258 | H24: 4 | I24: The Kid/Baby Glizz | J24: 1-2 | K24: -3 | L24: {=xlookup("The Kid/Baby Glizz",'Team Stats'!B:B,'Team Stats'!C:C)} -> 0.22727273

Sheet Season Stats
B2: Shooter | C2: Shooting | D2: Cups Made | E2: Cups Missed | F2: Splash-Out | G2: Guy | H2: Tri | I2: Di | J2: Un | K2: Vom
B3: Joe Raza | C3: =IFERROR((D3/(D3+E3)),0) -> 0.43589744 | D3: =SUMIFS(AllData!D:D, AllData!B:B, B3) -> 17 | E3: =SUMIFS(AllData!C:C, AllData!B:B, B3) -> 22 | F3: =SUMIFS(AllData!E:E, AllData!B:B, B3) -> 1 | G3: =SUMIFS(AllData!F:F, AllData!B:B, B3) -> 2 | H3: =SUMIFS(AllData!G:G, AllData!B:B, B3) -> 1 | I3: =SUMIFS(AllData!H:H, AllData!B:B, B3) -> 0 | J3: 0 | K3: =SUMIFS(AllData!I:I, AllData!B:B, B3) -> 0
B4: Charlie Truesdale | C4: =IFERROR((D4/(D4+E4)),0) -> 0.40740741 | D4: =SUMIFS(AllData!D:D, AllData!B:B, B4) -> 22 | E4: =SUMIFS(AllData!C:C, AllData!B:B, B4) -> 32 | F4: =SUMIFS(AllData!E:E, AllData!B:B, B4) -> 2 | G4: =SUMIFS(AllData!F:F, AllData!B:B, B4) -> 1 | H4: =SUMIFS(AllData!G:G, AllData!B:B, B4) -> 0 | I4: =SUMIFS(AllData!H:H, AllData!B:B, B4) -> 0 | J4: 0 | K4: =SUMIFS(AllData!I:I, AllData!B:B, B4) -> 0
B5: Zach Wilson | C5: =IFERROR((D5/(D5+E5)),0) -> 0.36842105 | D5: =SUMIFS(AllData!D:D, AllData!B:B, B5) -> 7 | E5: =SUMIFS(AllData!C:C, AllData!B:B, B5) -> 12 | F5: =SUMIFS(AllData!E:E, AllData!B:B, B5) -> 1 | G5: =SUMIFS(AllData!F:F, AllData!B:B, B5) -> 2 | H5: =SUMIFS(AllData!G:G, AllData!B:B, B5) -> 0 | I5: =SUMIFS(AllData!H:H, AllData!B:B, B5) -> 0 | J5: 0 | K5: =SUMIFS(AllData!I:I, AllData!B:B, B5) -> 0
B6: Heath Lawry | C6: =IFERROR((D6/(D6+E6)),0) -> 0.35714286 | D6: =SUMIFS(AllData!D:D, AllData!B:B, B6) -> 25 | E6: =SUMIFS(AllData!C:C, AllData!B:B, B6) -> 45 | F6: =SUMIFS(AllData!E:E, AllData!B:B, B6) -> 3 | G6: =SUMIFS(AllData!F:F, AllData!B:B, B6) -> 4 | H6: =SUMIFS(AllData!G:G, AllData!B:B, B6) -> 1 | I6: =SUMIFS(AllData!H:H, AllData!B:B, B6) -> 0 | J6: 0 | K6: =SUMIFS(AllData!I:I, AllData!B:B, B6) -> 0
B7: Matt Schreder | C7: =IFERROR((D7/(D7+E7)),0) -> 0.33333333 | D7: =SUMIFS(AllData!D:D, AllData!B:B, B7) -> 15 | E7: =SUMIFS(AllData!C:C, AllData!B:B, B7) -> 30 | F7: =SUMIFS(AllData!E:E, AllData!B:B, B7) -> 2 | G7: =SUMIFS(AllData!F:F, AllData!B:B, B7) -> 3 | H7: =SUMIFS(AllData!G:G, AllData!B:B, B7) -> 0 | I7: =SUMIFS(AllData!H:H, AllData!B:B, B7) -> 0 | J7: 0 | K7: =SUMIFS(AllData!I:I, AllData!B:B, B7) -> 1
B8: Charlie King | C8: =IFERROR((D8/(D8+E8)),0) -> 0.33333333 | D8: =SUMIFS(AllData!D:D, AllData!B:B, B8) -> 12 | E8: =SUMIFS(AllData!C:C, AllData!B:B, B8) -> 24 | F8: =SUMIFS(AllData!E:E, AllData!B:B, B8) -> 2 | G8: =SUMIFS(AllData!F:F, AllData!B:B, B8) -> 0 | H8: =SUMIFS(AllData!G:G, AllData!B:B, B8) -> 0 | I8: =SUMIFS(AllData!H:H, AllData!B:B, B8) -> 0 | J8: 0 | K8: =SUMIFS(AllData!I:I, AllData!B:B, B8) -> 0
B9: Drew Albright | C9: =IFERROR((D9/(D9+E9)),0) -> 0.32727273 | D9: =SUMIFS(AllData!D:D, AllData!B:B, B9) -> 18 | E9: =SUMIFS(AllData!C:C, AllData!B:B, B9) -> 37 | F9: =SUMIFS(AllData!E:E, AllData!B:B, B9) -> 5 | G9: =SUMIFS(AllData!F:F, AllData!B:B, B9) -> 0 | H9: =SUMIFS(AllData!G:G, AllData!B:B, B9) -> 0 | I9: =SUMIFS(AllData!H:H, AllData!B:B, B9) -> 0 | J9: 0 | K9: =SUMIFS(AllData!I:I, AllData!B:B, B9) -> 0
B10: Shawnak Shenoy | C10: =IFERROR((D10/(D10+E10)),0) -> 0.32258065 | D10: =SUMIFS(AllData!D:D, AllData!B:B, B10) -> 10 | E10: =SUMIFS(AllData!C:C, AllData!B:B, B10) -> 21 | F10: =SUMIFS(AllData!E:E, AllData!B:B, B10) -> 0 | G10: =SUMIFS(AllData!F:F, AllData!B:B, B10) -> 1 | H10: =SUMIFS(AllData!G:G, AllData!B:B, B10) -> 0 | I10: =SUMIFS(AllData!H:H, AllData!B:B, B10) -> 0 | J10: 0 | K10: =SUMIFS(AllData!I:I, AllData!B:B, B10) -> 0
B11: Will Creamer | C11: =IFERROR((D11/(D11+E11)),0) -> 0.32098765 | D11: =SUMIFS(AllData!D:D, AllData!B:B, B11) -> 26 | E11: =SUMIFS(AllData!C:C, AllData!B:B, B11) -> 55 | F11: =SUMIFS(AllData!E:E, AllData!B:B, B11) -> 1 | G11: =SUMIFS(AllData!F:F, AllData!B:B, B11) -> 7 | H11: =SUMIFS(AllData!G:G, AllData!B:B, B11) -> 1 | I11: =SUMIFS(AllData!H:H, AllData!B:B, B11) -> 0 | J11: 0 | K11: =SUMIFS(AllData!I:I, AllData!B:B, B11) -> 0
B12: Anson Mies | C12: =IFERROR((D12/(D12+E12)),0) -> 0.31914894 | D12: =SUMIFS(AllData!D:D, AllData!B:B, B12) -> 30 | E12: =SUMIFS(AllData!C:C, AllData!B:B, B12) -> 64 | F12: =SUMIFS(AllData!E:E, AllData!B:B, B12) -> 3 | G12: =SUMIFS(AllData!F:F, AllData!B:B, B12) -> 3 | H12: =SUMIFS(AllData!G:G, AllData!B:B, B12) -> 0 | I12: =SUMIFS(AllData!H:H, AllData!B:B, B12) -> 0 | J12: 0 | K12: =SUMIFS(AllData!I:I, AllData!B:B, B12) -> 0
B13: Brock Benton | C13: =IFERROR((D13/(D13+E13)),0) -> 0.3030303 | D13: =SUMIFS(AllData!D:D, AllData!B:B, B13) -> 20 | E13: =SUMIFS(AllData!C:C, AllData!B:B, B13) -> 46 | F13: =SUMIFS(AllData!E:E, AllData!B:B, B13) -> 4 | G13: =SUMIFS(AllData!F:F, AllData!B:B, B13) -> 3 | H13: =SUMIFS(AllData!G:G, AllData!B:B, B13) -> 0 | I13: =SUMIFS(AllData!H:H, AllData!B:B, B13) -> 0 | J13: 0 | K13: =SUMIFS(AllData!I:I, AllData!B:B, B13) -> 0
B14: Naman Kulkarni | C14: =IFERROR((D14/(D14+E14)),0) -> 0.30263158 | D14: =SUMIFS(AllData!D:D, AllData!B:B, B14) -> 23 | E14: =SUMIFS(AllData!C:C, AllData!B:B, B14) -> 53 | F14: =SUMIFS(AllData!E:E, AllData!B:B, B14) -> 3 | G14: =SUMIFS(AllData!F:F, AllData!B:B, B14) -> 5 | H14: =SUMIFS(AllData!G:G, AllData!B:B, B14) -> 0 | I14: =SUMIFS(AllData!H:H, AllData!B:B, B14) -> 0 | J14: 0 | K14: =SUMIFS(AllData!I:I, AllData!B:B, B14) -> 0
... B67: Andrew Mann | C67: =IFERROR((D67/(D67+E67)),0) -> 0.083333333 | D67: =SUMIFS(AllData!D:D, AllData!B:B, B67) -> 4 | E67: =SUMIFS(AllData!C:C, AllData!B:B, B67) -> 44 | F67: =SUMIFS(AllData!E:E, AllData!B:B, B67) -> 4 | G67: =SUMIFS(AllData!F:F, AllData!B:B, B67) -> 5 | H67: =SUMIFS(AllData!G:G, AllData!B:B, B67) -> 0 | I67: =SUMIFS(AllData!H:H, AllData!B:B, B67) -> 0 | J67: 0 | K67: =SUMIFS(AllData!I:I, AllData!B:B, B67) -> 0

Sheet Team Stats
B2: Team | C2: Shooting | D2: Cups Made | E2: Cups Missed | F2: Splash-Out | G2: Guy | H2: Tri | I2: Di | J2: Un | K2: Vom
B3: Charlie/Sarchio | C3: =IFERROR((D3/(D3+E3)),0) -> 0.33636364 | D3: =sumif('Season Stats'!$B$3:$B$66,"Charlie Truesdale",'Season Stats'!D$3:D$66)+sumif('Season Stats'!$B$3:$B$66, "Evan Sarchio",'Season Stats'!D$3:D$66) -> 37 | E3: =sumif('Season Stats'!$B$3:$B$66,"Charlie Truesdale",'Season Stats'!E$3:E$66)+sumif('Season Stats'!$B$3:$B$66, "Evan Sarchio",'Season Stats'!E$3:E$66) -> 73 | F3: =sumif('Season Stats'!$B$3:$B$66,"Charlie Truesdale",'Season Stats'!F$3:F$66)+sumif('Season Stats'!$B$3:$B$66, "Evan Sarchio",'Season Stats'!F$3:F$66) -> 5 | G3: =sumif('Season Stats'!$B$3:$B$66,"Charlie Truesdale",'Season Stats'!G$3:G$66)+sumif('Season Stats'!$B$3:$B$66, "Evan Sarchio",'Season Stats'!G$3:G$66) -> 3 | H3: =sumif('Season Stats'!$B$3:$B$66,"Charlie Truesdale",'Season Stats'!H$3:H$66)+sumif('Season Stats'!$B$3:$B$66, "Evan Sarchio",'Season Stats'!H$3:H$66) -> 0 | I3: =sumif('Season Stats'!$B$3:$B$66,"Charlie Truesdale",'Season Stats'!I$3:I$66)+sumif('Season Stats'!$B$3:$B$66, "Evan Sarchio",'Season Stats'!I$3:I$66) -> 0 | J3: =sumif('Season Stats'!$B$3:$B$66,"Charlie Truesdale",'Season Stats'!J$3:J$66)+sumif('Season Stats'!$B$3:$B$66, "Evan Sarchio",'Season Stats'!J$3:J$66) -> 0 | K3: =sumif('Season Stats'!$B$3:$B$66,"Charlie Truesdale",'Season Stats'!K$3:K$66)+sumif('Season Stats'!$B$3:$B$66, "Evan Sarchio",'Season Stats'!K$3:K$66) -> 0
B4: Blume/Raza | C4: =IFERROR((D4/(D4+E4)),0) -> 0.33333333 | D4: =sumif('Season Stats'!$B$3:$B$66,"Gabriel Blumenschein",'Season Stats'!D$3:D$66)+sumif('Season Stats'!$B$3:$B$66, "Joe Raza",'Season Stats'!D$3:D$66) -> 26 | E4: =sumif('Season Stats'!$B$3:$B$66,"Gabriel Blumenschein",'Season Stats'!E$3:E$66)+sumif('Season Stats'!$B$3:$B$66, "Joe Raza",'Season Stats'!E$3:E$66) -> 52 | F4: =sumif('Season Stats'!$B$3:$B$66,"Gabriel Blumenschein",'Season Stats'!F$3:F$66)+sumif('Season Stats'!$B$3:$B$66, "Joe Raza",'Season Stats'!F$3:F$66) -> 1 | G4: =sumif('Season Stats'!$B$3:$B$66,"Gabriel Blumenschein",'Season Stats'!G$3:G$66)+sumif('Season Stats'!$B$3:$B$66, "Joe Raza",'Season Stats'!G$3:G$66) -> 7 | H4: =sumif('Season Stats'!$B$3:$B$66,"Gabriel Blumenschein",'Season Stats'!H$3:H$66)+sumif('Season Stats'!$B$3:$B$66, "Joe Raza",'Season Stats'!H$3:H$66) -> 1 | I4: =sumif('Season Stats'!$B$3:$B$66,"Gabriel Blumenschein",'Season Stats'!I$3:I$66)+sumif('Season Stats'!$B$3:$B$66, "Joe Raza",'Season Stats'!I$3:I$66) -> 0 | J4: =sumif('Season Stats'!$B$3:$B$66,"Gabriel Blumenschein",'Season Stats'!J$3:J$66)+sumif('Season Stats'!$B$3:$B$66, "Joe Raza",'Season Stats'!J$3:J$66) -> 0 | K4: =sumif('Season Stats'!$B$3:$B$66,"Gabriel Blumenschein",'Season Stats'!K$3:K$66)+sumif('Season Stats'!$B$3:$B$66, "Joe Raza",'Season Stats'!K$3:K$66) -> 0
B5: Brando/Heath | C5: =IFERROR((D5/(D5+E5)),0) -> 0.32857143 | D5: =sumif('Season Stats'!$B$3:$B$66,"Luke Brandon",'Season Stats'!D$3:D$66)+sumif('Season Stats'!$B$3:$B$66, "Heath Lawry",'Season Stats'!D$3:D$66) -> 46 | E5: =sumif('Season Stats'!$B$3:$B$66,"Luke Brandon",'Season Stats'!E$3:E$66)+sumif('Season Stats'!$B$3:$B$66, "Heath Lawry",'Season Stats'!E$3:E$66) -> 94 | F5: =sumif('Season Stats'!$B$3:$B$66,"Luke Brandon",'Season Stats'!F$3:F$66)+sumif('Season Stats'!$B$3:$B$66, "Heath Lawry",'Season Stats'!F$3:F$66) -> 7 | G5: =sumif('Season Stats'!$B$3:$B$66,"Luke Brandon",'Season Stats'!G$3:G$66)+sumif('Season Stats'!$B$3:$B$66, "Heath Lawry",'Season Stats'!G$3:G$66) -> 5 | H5: =sumif('Season Stats'!$B$3:$B$66,"Luke Brandon",'Season Stats'!H$3:H$66)+sumif('Season Stats'!$B$3:$B$66, "Heath Lawry",'Season Stats'!H$3:H$66) -> 1 | I5: =sumif('Season Stats'!$B$3:$B$66,"Luke Brandon",'Season Stats'!I$3:I$66)+sumif('Season Stats'!$B$3:$B$66, "Heath Lawry",'Season Stats'!I$3:I$66) -> 0 | J5: =sumif('Season Stats'!$B$3:$B$66,"Luke Brandon",'Season Stats'!J$3:J$66)+sumif('Season Stats'!$B$3:$B$66, "Heath Lawry",'Season Stats'!J$3:J$66) -> 0 | K5: =sumif('Season Stats'!$B$3:$B$66,"Luke Brandon",'Season Stats'!K$3:K$66)+sumif('Season Stats'!$B$3:$B$66, "Heath Lawry",'Season Stats'!K$3:K$66) -> 0
B6: Creditor/King | C6: =IFERROR((D6/(D6+E6)),0) -> 0.31343284 | D6: =sumif('Season Stats'!$B$3:$B$66,"Max Creditor",'Season Stats'!D$3:D$66)+sumif('Season Stats'!$B$3:$B$66, "Charlie King",'Season Stats'!D$3:D$66) -> 21 | E6: =sumif('Season Stats'!$B$3:$B$66,"Max Creditor",'Season Stats'!E$3:E$66)+sumif('Season Stats'!$B$3:$B$66, "Charlie King",'Season Stats'!E$3:E$66) -> 46 | F6: =sumif('Season Stats'!$B$3:$B$66,"Max Creditor",'Season Stats'!F$3:F$66)+sumif('Season Stats'!$B$3:$B$66, "Charlie King",'Season Stats'!F$3:F$66) -> 6 | G6: =sumif('Season Stats'!$B$3:$B$66,"Max Creditor",'Season Stats'!G$3:G$66)+sumif('Season Stats'!$B$3:$B$66, "Charlie King",'Season Stats'!G$3:G$66) -> 1 | H6: =sumif('Season Stats'!$B$3:$B$66,"Max Creditor",'Season Stats'!H$3:H$66)+sumif('Season Stats'!$B$3:$B$66, "Charlie King",'Season Stats'!H$3:H$66) -> 0 | I6: =sumif('Season Stats'!$B$3:$B$66,"Max Creditor",'Season Stats'!I$3:I$66)+sumif('Season Stats'!$B$3:$B$66, "Charlie King",'Season Stats'!I$3:I$66) -> 0 | J6: =sumif('Season Stats'!$B$3:$B$66,"Max Creditor",'Season Stats'!J$3:J$66)+sumif('Season Stats'!$B$3:$B$66, "Charlie King",'Season Stats'!J$3:J$66) -> 0 | K6: =sumif('Season Stats'!$B$3:$B$66,"Max Creditor",'Season Stats'!K$3:K$66)+sumif('Season Stats'!$B$3:$B$66, "Charlie King",'Season Stats'!K$3:K$66) -> 1
B7: Shawnak/Mackie | C7: =IFERROR((D7/(D7+E7)),0) -> 0.29032258 | D7: =sumif('Season Stats'!$B$3:$B$66,"Shawnak Shenoy",'Season Stats'!D$3:D$66)+sumif('Season Stats'!$B$3:$B$66, "Mackie Wallwork",'Season Stats'!D$3:D$66) -> 18 | E7: =sumif('Season Stats'!$B$3:$B$66,"Shawnak Shenoy",'Season Stats'!E$3:E$66)+sumif('Season Stats'!$B$3:$B$66, "Mackie Wallwork",'Season Stats'!E$3:E$66) -> 44 | F7: =sumif('Season Stats'!$B$3:$B$66,"Shawnak Shenoy",'Season Stats'!F$3:F$66)+sumif('Season Stats'!$B$3:$B$66, "Mackie Wallwork",'Season Stats'!F$3:F$66) -> 1 | G7: =sumif('Season Stats'!$B$3:$B$66,"Shawnak Shenoy",'Season Stats'!G$3:G$66)+sumif('Season Stats'!$B$3:$B$66, "Mackie Wallwork",'Season Stats'!G$3:G$66) -> 2 | H7: =sumif('Season Stats'!$B$3:$B$66,"Shawnak Shenoy",'Season Stats'!H$3:H$66)+sumif('Season Stats'!$B$3:$B$66, "Mackie Wallwork",'Season Stats'!H$3:H$66) -> 0 | I7: =sumif('Season Stats'!$B$3:$B$66,"Shawnak Shenoy",'Season Stats'!I$3:I$66)+sumif('Season Stats'!$B$3:$B$66, "Mackie Wallwork",'Season Stats'!I$3:I$66) -> 0 | J7: =sumif('Season Stats'!$B$3:$B$66,"Shawnak Shenoy",'Season Stats'!J$3:J$66)+sumif('Season Stats'!$B$3:$B$66, "Mackie Wallwork",'Season Stats'!J$3:J$66) -> 0 | K7: =sumif('Season Stats'!$B$3:$B$66,"Shawnak Shenoy",'Season Stats'!K$3:K$66)+sumif('Season Stats'!$B$3:$B$66, "Mackie Wallwork",'Season Stats'!K$3:K$66) -> 0
B8: Creamer/Hudson | C8: =IFERROR((D8/(D8+E8)),0) -> 0.2875 | D8: =sumif('Season Stats'!$B$3:$B$66,"Will Creamer",'Season Stats'!D$3:D$66)+sumif('Season Stats'!$B$3:$B$66, "Hudson Stolz",'Season Stats'!D$3:D$66) -> 46 | E8: =sumif('Season Stats'!$B$3:$B$66,"Will Creamer",'Season Stats'!E$3:E$66)+sumif('Season Stats'!$B$3:$B$66, "Hudson Stolz",'Season Stats'!E$3:E$66) -> 114 | F8: =sumif('Season Stats'!$B$3:$B$66,"Will Creamer",'Season Stats'!F$3:F$66)+sumif('Season Stats'!$B$3:$B$66, "Hudson Stolz",'Season Stats'!F$3:F$66) -> 5 | G8: =sumif('Season Stats'!$B$3:$B$66,"Will Creamer",'Season Stats'!G$3:G$66)+sumif('Season Stats'!$B$3:$B$66, "Hudson Stolz",'Season Stats'!G$3:G$66) -> 11 | H8: =sumif('Season Stats'!$B$3:$B$66,"Will Creamer",'Season Stats'!H$3:H$66)+sumif('Season Stats'!$B$3:$B$66, "Hudson Stolz",'Season Stats'!H$3:H$66) -> 1 | I8: =sumif('Season Stats'!$B$3:$B$66,"Will Creamer",'Season Stats'!I$3:I$66)+sumif('Season Stats'!$B$3:$B$66, "Hudson Stolz",'Season Stats'!I$3:I$66) -> 0 | J8: =sumif('Season Stats'!$B$3:$B$66,"Will Creamer",'Season Stats'!J$3:J$66)+sumif('Season Stats'!$B$3:$B$66, "Hudson Stolz",'Season Stats'!J$3:J$66) -> 0 | K8: =sumif('Season Stats'!$B$3:$B$66,"Will Creamer",'Season Stats'!K$3:K$66)+sumif('Season Stats'!$B$3:$B$66, "Hudson Stolz",'Season Stats'!K$3:K$66) -> 0
B9: Schreder/Dylan and Matian | C9: =IFERROR((D9/(D9+E9)),0) -> 0.28723404 | D9: =sumif('Season Stats'!$B$3:$B$66,"Matt Schreder",'Season Stats'!D$3:D$66)+sumif('Season Stats'!$B$3:$B$66, "Dylan and Matian",'Season Stats'!D$3:D$66) -> 27 | E9: =sumif('Season Stats'!$B$3:$B$66,"Matt Schreder",'Season Stats'!E$3:E$66)+sumif('Season Stats'!$B$3:$B$66, "Dylan and Matian",'Season Stats'!E$3:E$66) -> 67 | F9: =sumif('Season Stats'!$B$3:$B$66,"Matt Schreder",'Season Stats'!F$3:F$66)+sumif('Season Stats'!$B$3:$B$66, "Dylan and Matian",'Season Stats'!F$3:F$66) -> 5 | G9: =sumif('Season Stats'!$B$3:$B$66,"Matt Schreder",'Season Stats'!G$3:G$66)+sumif('Season Stats'!$B$3:$B$66, "Dylan and Matian",'Season Stats'!G$3:G$66) -> 4 | H9: =sumif('Season Stats'!$B$3:$B$66,"Matt Schreder",'Season Stats'!H$3:H$66)+sumif('Season Stats'!$B$3:$B$66, "Dylan and Matian",'Season Stats'!H$3:H$66) -> 0 | I9: =sumif('Season Stats'!$B$3:$B$66,"Matt Schreder",'Season Stats'!I$3:I$66)+sumif('Season Stats'!$B$3:$B$66, "Dylan and Matian",'Season Stats'!I$3:I$66) -> 0 | J9: =sumif('Season Stats'!$B$3:$B$66,"Matt Schreder",'Season Stats'!J$3:J$66)+sumif('Season Stats'!$B$3:$B$66, "Dylan and Matian",'Season Stats'!J$3:J$66) -> 0 | K9: =sumif('Season Stats'!$B$3:$B$66,"Matt Schreder",'Season Stats'!K$3:K$66)+sumif('Season Stats'!$B$3:$B$66, "Dylan and Matian",'Season Stats'!K$3:K$66) -> 1
B10: Anson/Pierre | C10: =IFERROR((D10/(D10+E10)),0) -> 0.28494624 | D10: =sumif('Season Stats'!$B$3:$B$66,"Anson Mies",'Season Stats'!D$3:D$66)+sumif('Season Stats'!$B$3:$B$66, "Pierre Gathy",'Season Stats'!D$3:D$66) -> 53 | E10: =sumif('Season Stats'!$B$3:$B$66,"Anson Mies",'Season Stats'!E$3:E$66)+sumif('Season Stats'!$B$3:$B$66, "Pierre Gathy",'Season Stats'!E$3:E$66) -> 133 | F10: =sumif('Season Stats'!$B$3:$B$66,"Anson Mies",'Season Stats'!F$3:F$66)+sumif('Season Stats'!$B$3:$B$66, "Pierre Gathy",'Season Stats'!F$3:F$66) -> 9 | G10: =sumif('Season Stats'!$B$3:$B$66,"Anson Mies",'Season Stats'!G$3:G$66)+sumif('Season Stats'!$B$3:$B$66, "Pierre Gathy",'Season Stats'!G$3:G$66) -> 4 | H10: =sumif('Season Stats'!$B$3:$B$66,"Anson Mies",'Season Stats'!H$3:H$66)+sumif('Season Stats'!$B$3:$B$66, "Pierre Gathy",'Season Stats'!H$3:H$66) -> 0 | I10: =sumif('Season Stats'!$B$3:$B$66,"Anson Mies",'Season Stats'!I$3:I$66)+sumif('Season Stats'!$B$3:$B$66, "Pierre Gathy",'Season Stats'!I$3:I$66) -> 0 | J10: =sumif('Season Stats'!$B$3:$B$66,"Anson Mies",'Season Stats'!J$3:J$66)+sumif('Season Stats'!$B$3:$B$66, "Pierre Gathy",'Season Stats'!J$3:J$66) -> 0 | K10: =sumif('Season Stats'!$B$3:$B$66,"Anson Mies",'Season Stats'!K$3:K$66)+sumif('Season Stats'!$B$3:$B$66, "Pierre Gathy",'Season Stats'!K$3:K$66) -> 0
B11: Wigs/Boggs | C11: =IFERROR((D11/(D11+E11)),0) -> 0.27722772 | D11: =sumif('Season Stats'!$B$3:$B$66,"Jack Wigmore",'Season Stats'!D$3:D$66)+sumif('Season Stats'!$B$3:$B$66, "Charlie Boggs",'Season Stats'!D$3:D$66) -> 56 | E11: =sumif('Season Stats'!$B$3:$B$66,"Jack Wigmore",'Season Stats'!E$3:E$66)+sumif('Season Stats'!$B$3:$B$66, "Charlie Boggs",'Season Stats'!E$3:E$66) -> 146 | F11: =sumif('Season Stats'!$B$3:$B$66,"Jack Wigmore",'Season Stats'!F$3:F$66)+sumif('Season Stats'!$B$3:$B$66, "Charlie Boggs",'Season Stats'!F$3:F$66) -> 6 | G11: =sumif('Season Stats'!$B$3:$B$66,"Jack Wigmore",'Season Stats'!G$3:G$66)+sumif('Season Stats'!$B$3:$B$66, "Charlie Boggs",'Season Stats'!G$3:G$66) -> 8 | H11: =sumif('Season Stats'!$B$3:$B$66,"Jack Wigmore",'Season Stats'!H$3:H$66)+sumif('Season Stats'!$B$3:$B$66, "Charlie Boggs",'Season Stats'!H$3:H$66) -> 0 | I11: =sumif('Season Stats'!$B$3:$B$66,"Jack Wigmore",'Season Stats'!I$3:I$66)+sumif('Season Stats'!$B$3:$B$66, "Charlie Boggs",'Season Stats'!I$3:I$66) -> 0 | J11: =sumif('Season Stats'!$B$3:$B$66,"Jack Wigmore",'Season Stats'!J$3:J$66)+sumif('Season Stats'!$B$3:$B$66, "Charlie Boggs",'Season Stats'!J$3:J$66) -> 0 | K11: =sumif('Season Stats'!$B$3:$B$66,"Jack Wigmore",'Season Stats'!K$3:K$66)+sumif('Season Stats'!$B$3:$B$66, "Charlie Boggs",'Season Stats'!K$3:K$66) -> 1
B12: Brock/Vinny | C12: =IFERROR((D12/(D12+E12)),0) -> 0.26515152 | D12: =sumif('Season Stats'!$B$3:$B$66,"Brock Benton",'Season Stats'!D$3:D$66)+sumif('Season Stats'!$B$3:$B$66, "Vinny Drolet",'Season Stats'!D$3:D$66) -> 35 | E12: =sumif('Season Stats'!$B$3:$B$66,"Brock Benton",'Season Stats'!E$3:E$66)+sumif('Season Stats'!$B$3:$B$66, "Vinny Drolet",'Season Stats'!E$3:E$66) -> 97 | F12: =sumif('Season Stats'!$B$3:$B$66,"Brock Benton",'Season Stats'!F$3:F$66)+sumif('Season Stats'!$B$3:$B$66, "Vinny Drolet",'Season Stats'!F$3:F$66) -> 5 | G12: =sumif('Season Stats'!$B$3:$B$66,"Brock Benton",'Season Stats'!G$3:G$66)+sumif('Season Stats'!$B$3:$B$66, "Vinny Drolet",'Season Stats'!G$3:G$66) -> 6 | H12: =sumif('Season Stats'!$B$3:$B$66,"Brock Benton",'Season Stats'!H$3:H$66)+sumif('Season Stats'!$B$3:$B$66, "Vinny Drolet",'Season Stats'!H$3:H$66) -> 0 | I12: =sumif('Season Stats'!$B$3:$B$66,"Brock Benton",'Season Stats'!I$3:I$66)+sumif('Season Stats'!$B$3:$B$66, "Vinny Drolet",'Season Stats'!I$3:I$66) -> 0 | J12: =sumif('Season Stats'!$B$3:$B$66,"Brock Benton",'Season Stats'!J$3:J$66)+sumif('Season Stats'!$B$3:$B$66, "Vinny Drolet",'Season Stats'!J$3:J$66) -> 0 | K12: =sumif('Season Stats'!$B$3:$B$66,"Brock Benton",'Season Stats'!K$3:K$66)+sumif('Season Stats'!$B$3:$B$66, "Vinny Drolet",'Season Stats'!K$3:K$66) -> 0
B13: Mati/Takoa | C13: =IFERROR((D13/(D13+E13)),0) -> 0.26229508 | D13: =sumif('Season Stats'!$B$3:$B$66,"Mati Gandarias",'Season Stats'!D$3:D$66)+sumif('Season Stats'!$B$3:$B$66, "Takoa Cartwright",'Season Stats'!D$3:D$66) -> 48 | E13: =sumif('Season Stats'!$B$3:$B$66,"Mati Gandarias",'Season Stats'!E$3:E$66)+sumif('Season Stats'!$B$3:$B$66, "Takoa Cartwright",'Season Stats'!E$3:E$66) -> 135 | F13: =sumif('Season Stats'!$B$3:$B$66,"Mati Gandarias",'Season Stats'!F$3:F$66)+sumif('Season Stats'!$B$3:$B$66, "Takoa Cartwright",'Season Stats'!F$3:F$66) -> 7 | G13: =sumif('Season Stats'!$B$3:$B$66,"Mati Gandarias",'Season Stats'!G$3:G$66)+sumif('Season Stats'!$B$3:$B$66, "Takoa Cartwright",'Season Stats'!G$3:G$66) -> 8 | H13: =sumif('Season Stats'!$B$3:$B$66,"Mati Gandarias",'Season Stats'!H$3:H$66)+sumif('Season Stats'!$B$3:$B$66, "Takoa Cartwright",'Season Stats'!H$3:H$66) -> 0 | I13: =sumif('Season Stats'!$B$3:$B$66,"Mati Gandarias",'Season Stats'!I$3:I$66)+sumif('Season Stats'!$B$3:$B$66, "Takoa Cartwright",'Season Stats'!I$3:I$66) -> 0 | J13: =sumif('Season Stats'!$B$3:$B$66,"Mati Gandarias",'Season Stats'!J$3:J$66)+sumif('Season Stats'!$B$3:$B$66, "Takoa Cartwright",'Season Stats'!J$3:J$66) -> 0 | K13: =sumif('Season Stats'!$B$3:$B$66,"Mati Gandarias",'Season Stats'!K$3:K$66)+sumif('Season Stats'!$B$3:$B$66, "Takoa Cartwright",'Season Stats'!K$3:K$66) -> 0
B14: Cestero/Messina | C14: =IFERROR((D14/(D14+E14)),0) -> 0.26213592 | D14: =sumif('Season Stats'!$B$3:$B$66,"Josh Cestero",'Season Stats'!D$3:D$66)+sumif('Season Stats'!$B$3:$B$66, "Michael Messina",'Season Stats'!D$3:D$66) -> 27 | E14: =sumif('Season Stats'!$B$3:$B$66,"Josh Cestero",'Season Stats'!E$3:E$66)+sumif('Season Stats'!$B$3:$B$66, "Michael Messina",'Season Stats'!E$3:E$66) -> 76 | F14: =sumif('Season Stats'!$B$3:$B$66,"Josh Cestero",'Season Stats'!F$3:F$66)+sumif('Season Stats'!$B$3:$B$66, "Michael Messina",'Season Stats'!F$3:F$66) -> 4 | G14: =sumif('Season Stats'!$B$3:$B$66,"Josh Cestero",'Season Stats'!G$3:G$66)+sumif('Season Stats'!$B$3:$B$66, "Michael Messina",'Season Stats'!G$3:G$66) -> 4 | H14: =sumif('Season Stats'!$B$3:$B$66,"Josh Cestero",'Season Stats'!H$3:H$66)+sumif('Season Stats'!$B$3:$B$66, "Michael Messina",'Season Stats'!H$3:H$66) -> 0 | I14: =sumif('Season Stats'!$B$3:$B$66,"Josh Cestero",'Season Stats'!I$3:I$66)+sumif('Season Stats'!$B$3:$B$66, "Michael Messina",'Season Stats'!I$3:I$66) -> 0 | J14: =sumif('Season Stats'!$B$3:$B$66,"Josh Cestero",'Season Stats'!J$3:J$66)+sumif('Season Stats'!$B$3:$B$66, "Michael Messina",'Season Stats'!J$3:J$66) -> 0 | K14: =sumif('Season Stats'!$B$3:$B$66,"Josh Cestero",'Season Stats'!K$3:K$66)+sumif('Season Stats'!$B$3:$B$66, "Michael Messina",'Season Stats'!K$3:K$66) -> 0
B15: JP/Ford | C15: =IFERROR((D15/(D15+E15)),0) -> 0.24683544 | D15: =sumif('Season Stats'!$B$3:$B$66,"Jaden Pearlmutter",'Season Stats'!D$3:D$66)+sumif('Season Stats'!$B$3:$B$66, "Ford Tate",'Season Stats'!D$3:D$66) -> 39 | E15: =sumif('Season Stats'!$B$3:$B$66,"Jaden Pearlmutter",'Season Stats'!E$3:E$66)+sumif('Season Stats'!$B$3:$B$66, "Ford Tate",'Season Stats'!E$3:E$66) -> 119 | F15: =sumif('Season Stats'!$B$3:$B$66,"Jaden Pearlmutter",'Season Stats'!F$3:F$66)+sumif('Season Stats'!$B$3:$B$66, "Ford Tate",'Season Stats'!F$3:F$66) -> 1 | G15: =sumif('Season Stats'!$B$3:$B$66,"Jaden Pearlmutter",'Season Stats'!G$3:G$66)+sumif('Season Stats'!$B$3:$B$66, "Ford Tate",'Season Stats'!G$3:G$66) -> 3 | H15: =sumif('Season Stats'!$B$3:$B$66,"Jaden Pearlmutter",'Season Stats'!H$3:H$66)+sumif('Season Stats'!$B$3:$B$66, "Ford Tate",'Season Stats'!H$3:H$66) -> 0 | I15: =sumif('Season Stats'!$B$3:$B$66,"Jaden Pearlmutter",'Season Stats'!I$3:I$66)+sumif('Season Stats'!$B$3:$B$66, "Ford Tate",'Season Stats'!I$3:I$66) -> 0 | J15: =sumif('Season Stats'!$B$3:$B$66,"Jaden Pearlmutter",'Season Stats'!J$3:J$66)+sumif('Season Stats'!$B$3:$B$66, "Ford Tate",'Season Stats'!J$3:J$66) -> 0 | K15: =sumif('Season Stats'!$B$3:$B$66,"Jaden Pearlmutter",'Season Stats'!K$3:K$66)+sumif('Season Stats'!$B$3:$B$66, "Ford Tate",'Season Stats'!K$3:K$66) -> 0
B16: Naman/Liam | C16: =IFERROR((D16/(D16+E16)),0) -> 0.24503311 | D16: =sumif('Season Stats'!$B$3:$B$66,"Naman Kulkarni",'Season Stats'!D$3:D$66)+sumif('Season Stats'!$B$3:$B$66, "Liam Byrne",'Season Stats'!D$3:D$66) -> 37 | E16: =sumif('Season Stats'!$B$3:$B$66,"Naman Kulkarni",'Season Stats'!E$3:E$66)+sumif('Season Stats'!$B$3:$B$66, "Liam Byrne",'Season Stats'!E$3:E$66) -> 114 | F16: =sumif('Season Stats'!$B$3:$B$66,"Naman Kulkarni",'Season Stats'!F$3:F$66)+sumif('Season Stats'!$B$3:$B$66, "Liam Byrne",'Season Stats'!F$3:F$66) -> 9 | G16: =sumif('Season Stats'!$B$3:$B$66,"Naman Kulkarni",'Season Stats'!G$3:G$66)+sumif('Season Stats'!$B$3:$B$66, "Liam Byrne",'Season Stats'!G$3:G$66) -> 6 | H16: =sumif('Season Stats'!$B$3:$B$66,"Naman Kulkarni",'Season Stats'!H$3:H$66)+sumif('Season Stats'!$B$3:$B$66, "Liam Byrne",'Season Stats'!H$3:H$66) -> 0 | I16: =sumif('Season Stats'!$B$3:$B$66,"Naman Kulkarni",'Season Stats'!I$3:I$66)+sumif('Season Stats'!$B$3:$B$66, "Liam Byrne",'Season Stats'!I$3:I$66) -> 0 | J16: =sumif('Season Stats'!$B$3:$B$66,"Naman Kulkarni",'Season Stats'!J$3:J$66)+sumif('Season Stats'!$B$3:$B$66, "Liam Byrne",'Season Stats'!J$3:J$66) -> 0 | K16: =sumif('Season Stats'!$B$3:$B$66,"Naman Kulkarni",'Season Stats'!K$3:K$66)+sumif('Season Stats'!$B$3:$B$66, "Liam Byrne",'Season Stats'!K$3:K$66) -> 0
B17: Kavishka/Akash | C17: =IFERROR((D17/(D17+E17)),0) -> 0.24 | D17: =sumif('Season Stats'!$B$3:$B$66,"Kavishka Bartlett",'Season Stats'!D$3:D$66)+sumif('Season Stats'!$B$3:$B$66, "Akash Mishra",'Season Stats'!D$3:D$66) -> 24 | E17: =sumif('Season Stats'!$B$3:$B$66,"Kavishka Bartlett",'Season Stats'!E$3:E$66)+sumif('Season Stats'!$B$3:$B$66, "Akash Mishra",'Season Stats'!E$3:E$66) -> 76 | F17: =sumif('Season Stats'!$B$3:$B$66,"Kavishka Bartlett",'Season Stats'!F$3:F$66)+sumif('Season Stats'!$B$3:$B$66, "Akash Mishra",'Season Stats'!F$3:F$66) -> 6 | G17: =sumif('Season Stats'!$B$3:$B$66,"Kavishka Bartlett",'Season Stats'!G$3:G$66)+sumif('Season Stats'!$B$3:$B$66, "Akash Mishra",'Season Stats'!G$3:G$66) -> 8 | H17: =sumif('Season Stats'!$B$3:$B$66,"Kavishka Bartlett",'Season Stats'!H$3:H$66)+sumif('Season Stats'!$B$3:$B$66, "Akash Mishra",'Season Stats'!H$3:H$66) -> 0 | I17: =sumif('Season Stats'!$B$3:$B$66,"Kavishka Bartlett",'Season Stats'!I$3:I$66)+sumif('Season Stats'!$B$3:$B$66, "Akash Mishra",'Season Stats'!I$3:I$66) -> 0 | J17: =sumif('Season Stats'!$B$3:$B$66,"Kavishka Bartlett",'Season Stats'!J$3:J$66)+sumif('Season Stats'!$B$3:$B$66, "Akash Mishra",'Season Stats'!J$3:J$66) -> 0 | K17: =sumif('Season Stats'!$B$3:$B$66,"Kavishka Bartlett",'Season Stats'!K$3:K$66)+sumif('Season Stats'!$B$3:$B$66, "Akash Mishra",'Season Stats'!K$3:K$66) -> 0
B18: Emilio/Tolsma | C18: =IFERROR((D18/(D18+E18)),0) -> 0.23809524 | D18: =sumif('Season Stats'!$B$3:$B$66,"Emilio Garcia",'Season Stats'!D$3:D$66)+sumif('Season Stats'!$B$3:$B$66, "John Tolsma",'Season Stats'!D$3:D$66) -> 35 | E18: =sumif('Season Stats'!$B$3:$B$66,"Emilio Garcia",'Season Stats'!E$3:E$66)+sumif('Season Stats'!$B$3:$B$66, "John Tolsma",'Season Stats'!E$3:E$66) -> 112 | F18: =sumif('Season Stats'!$B$3:$B$66,"Emilio Garcia",'Season Stats'!F$3:F$66)+sumif('Season Stats'!$B$3:$B$66, "John Tolsma",'Season Stats'!F$3:F$66) -> 3 | G18: =sumif('Season Stats'!$B$3:$B$66,"Emilio Garcia",'Season Stats'!G$3:G$66)+sumif('Season Stats'!$B$3:$B$66, "John Tolsma",'Season Stats'!G$3:G$66) -> 12 | H18: =sumif('Season Stats'!$B$3:$B$66,"Emilio Garcia",'Season Stats'!H$3:H$66)+sumif('Season Stats'!$B$3:$B$66, "John Tolsma",'Season Stats'!H$3:H$66) -> 0 | I18: =sumif('Season Stats'!$B$3:$B$66,"Emilio Garcia",'Season Stats'!I$3:I$66)+sumif('Season Stats'!$B$3:$B$66, "John Tolsma",'Season Stats'!I$3:I$66) -> 0 | J18: =sumif('Season Stats'!$B$3:$B$66,"Emilio Garcia",'Season Stats'!J$3:J$66)+sumif('Season Stats'!$B$3:$B$66, "John Tolsma",'Season Stats'!J$3:J$66) -> 0 | K18: =sumif('Season Stats'!$B$3:$B$66,"Emilio Garcia",'Season Stats'!K$3:K$66)+sumif('Season Stats'!$B$3:$B$66, "John Tolsma",'Season Stats'!K$3:K$66) -> 0
B19: Albright/Wilder | C19: =IFERROR((D19/(D19+E19)),0) -> 0.23636364 | D19: =sumif('Season Stats'!$B$3:$B$66,"Drew Albright",'Season Stats'!D$3:D$66)+sumif('Season Stats'!$B$3:$B$66, "Jack Wilder",'Season Stats'!D$3:D$66) -> 26 | E19: =sumif('Season Stats'!$B$3:$B$66,"Drew Albright",'Season Stats'!E$3:E$66)+sumif('Season Stats'!$B$3:$B$66, "Jack Wilder",'Season Stats'!E$3:E$66) -> 84 | F19: =sumif('Season Stats'!$B$3:$B$66,"Drew Albright",'Season Stats'!F$3:F$66)+sumif('Season Stats'!$B$3:$B$66, "Jack Wilder",'Season Stats'!F$3:F$66) -> 8 | G19: =sumif('Season Stats'!$B$3:$B$66,"Drew Albright",'Season Stats'!G$3:G$66)+sumif('Season Stats'!$B$3:$B$66, "Jack Wilder",'Season Stats'!G$3:G$66) -> 7 | H19: =sumif('Season Stats'!$B$3:$B$66,"Drew Albright",'Season Stats'!H$3:H$66)+sumif('Season Stats'!$B$3:$B$66, "Jack Wilder",'Season Stats'!H$3:H$66) -> 0 | I19: =sumif('Season Stats'!$B$3:$B$66,"Drew Albright",'Season Stats'!I$3:I$66)+sumif('Season Stats'!$B$3:$B$66, "Jack Wilder",'Season Stats'!I$3:I$66) -> 0 | J19: =sumif('Season Stats'!$B$3:$B$66,"Drew Albright",'Season Stats'!J$3:J$66)+sumif('Season Stats'!$B$3:$B$66, "Jack Wilder",'Season Stats'!J$3:J$66) -> 0 | K19: =sumif('Season Stats'!$B$3:$B$66,"Drew Albright",'Season Stats'!K$3:K$66)+sumif('Season Stats'!$B$3:$B$66, "Jack Wilder",'Season Stats'!K$3:K$66) -> 0
B20: Toban/Homo | C20: =IFERROR((D20/(D20+E20)),0) -> 0.23076923 | D20: =sumif('Season Stats'!$B$3:$B$66,"Toban Doody",'Season Stats'!D$3:D$66)+sumif('Season Stats'!$B$3:$B$66, "Henry Morrison",'Season Stats'!D$3:D$66) -> 33 | E20: =sumif('Season Stats'!$B$3:$B$66,"Toban Doody",'Season Stats'!E$3:E$66)+sumif('Season Stats'!$B$3:$B$66, "Henry Morrison",'Season Stats'!E$3:E$66) -> 110 | F20: =sumif('Season Stats'!$B$3:$B$66,"Toban Doody",'Season Stats'!F$3:F$66)+sumif('Season Stats'!$B$3:$B$66, "Henry Morrison",'Season Stats'!F$3:F$66) -> 3 | G20: =sumif('Season Stats'!$B$3:$B$66,"Toban Doody",'Season Stats'!G$3:G$66)+sumif('Season Stats'!$B$3:$B$66, "Henry Morrison",'Season Stats'!G$3:G$66) -> 8 | H20: =sumif('Season Stats'!$B$3:$B$66,"Toban Doody",'Season Stats'!H$3:H$66)+sumif('Season Stats'!$B$3:$B$66, "Henry Morrison",'Season Stats'!H$3:H$66) -> 0 | I20: =sumif('Season Stats'!$B$3:$B$66,"Toban Doody",'Season Stats'!I$3:I$66)+sumif('Season Stats'!$B$3:$B$66, "Henry Morrison",'Season Stats'!I$3:I$66) -> 0 | J20: =sumif('Season Stats'!$B$3:$B$66,"Toban Doody",'Season Stats'!J$3:J$66)+sumif('Season Stats'!$B$3:$B$66, "Henry Morrison",'Season Stats'!J$3:J$66) -> 0 | K20: =sumif('Season Stats'!$B$3:$B$66,"Toban Doody",'Season Stats'!K$3:K$66)+sumif('Season Stats'!$B$3:$B$66, "Henry Morrison",'Season Stats'!K$3:K$66) -> 1
B21: The Kid/Baby Glizz | C21: =IFERROR((D21/(D21+E21)),0) -> 0.22727273 | D21: =sumif('Season Stats'!$B$3:$B$66,"AJ Cashman",'Season Stats'!D$3:D$66)+sumif('Season Stats'!$B$3:$B$66, "Zach Israel",'Season Stats'!D$3:D$66) -> 25 | E21: =sumif('Season Stats'!$B$3:$B$66,"AJ Cashman",'Season Stats'!E$3:E$66)+sumif('Season Stats'!$B$3:$B$66, "Zach Israel",'Season Stats'!E$3:E$66) -> 85 | F21: =sumif('Season Stats'!$B$3:$B$66,"AJ Cashman",'Season Stats'!F$3:F$66)+sumif('Season Stats'!$B$3:$B$66, "Zach Israel",'Season Stats'!F$3:F$66) -> 5 | G21: =sumif('Season Stats'!$B$3:$B$66,"AJ Cashman",'Season Stats'!G$3:G$66)+sumif('Season Stats'!$B$3:$B$66, "Zach Israel",'Season Stats'!G$3:G$66) -> 5 | H21: =sumif('Season Stats'!$B$3:$B$66,"AJ Cashman",'Season Stats'!H$3:H$66)+sumif('Season Stats'!$B$3:$B$66, "Zach Israel",'Season Stats'!H$3:H$66) -> 0 | I21: =sumif('Season Stats'!$B$3:$B$66,"AJ Cashman",'Season Stats'!I$3:I$66)+sumif('Season Stats'!$B$3:$B$66, "Zach Israel",'Season Stats'!I$3:I$66) -> 0 | J21: =sumif('Season Stats'!$B$3:$B$66,"AJ Cashman",'Season Stats'!J$3:J$66)+sumif('Season Stats'!$B$3:$B$66, "Zach Israel",'Season Stats'!J$3:J$66) -> 0 | K21: =sumif('Season Stats'!$B$3:$B$66,"AJ Cashman",'Season Stats'!K$3:K$66)+sumif('Season Stats'!$B$3:$B$66, "Zach Israel",'Season Stats'!K$3:K$66) -> 0
B22: Alejandro/Bonn | C22: =IFERROR((D22/(D22+E22)),0) -> 0.22413793 | D22: =sumif('Season Stats'!$B$3:$B$66,"Alejandro Montero",'Season Stats'!D$3:D$66)+sumif('Season Stats'!$B$3:$B$66, "Max Bonnstetter",'Season Stats'!D$3:D$66) -> 26 | E22: =sumif('Season Stats'!$B$3:$B$66,"Alejandro Montero",'Season Stats'!E$3:E$66)+sumif('Season Stats'!$B$3:$B$66, "Max Bonnstetter",'Season Stats'!E$3:E$66) -> 90 | F22: =sumif('Season Stats'!$B$3:$B$66,"Alejandro Montero",'Season Stats'!F$3:F$66)+sumif('Season Stats'!$B$3:$B$66, "Max Bonnstetter",'Season Stats'!F$3:F$66) -> 2 | G22: =sumif('Season Stats'!$B$3:$B$66,"Alejandro Montero",'Season Stats'!G$3:G$66)+sumif('Season Stats'!$B$3:$B$66, "Max Bonnstetter",'Season Stats'!G$3:G$66) -> 10 | H22: =sumif('Season Stats'!$B$3:$B$66,"Alejandro Montero",'Season Stats'!H$3:H$66)+sumif('Season Stats'!$B$3:$B$66, "Max Bonnstetter",'Season Stats'!H$3:H$66) -> 0 | I22: =sumif('Season Stats'!$B$3:$B$66,"Alejandro Montero",'Season Stats'!I$3:I$66)+sumif('Season Stats'!$B$3:$B$66, "Max Bonnstetter",'Season Stats'!I$3:I$66) -> 0 | J22: =sumif('Season Stats'!$B$3:$B$66,"Alejandro Montero",'Season Stats'!J$3:J$66)+sumif('Season Stats'!$B$3:$B$66, "Max Bonnstetter",'Season Stats'!J$3:J$66) -> 0 | K22: =sumif('Season Stats'!$B$3:$B$66,"Alejandro Montero",'Season Stats'!K$3:K$66)+sumif('Season Stats'!$B$3:$B$66, "Max Bonnstetter",'Season Stats'!K$3:K$66) -> 1
B23: Isaiah/Mike Miller | C23: =IFERROR((D23/(D23+E23)),0) -> 0.22368421 | D23: =sumif('Season Stats'!$B$3:$B$66,"Isaiah Boyles",'Season Stats'!D$3:D$66)+sumif('Season Stats'!$B$3:$B$66, "Mike Miller",'Season Stats'!D$3:D$66) -> 17 | E23: =sumif('Season Stats'!$B$3:$B$66,"Isaiah Boyles",'Season Stats'!E$3:E$66)+sumif('Season Stats'!$B$3:$B$66, "Mike Miller",'Season Stats'!E$3:E$66) -> 59 | F23: =sumif('Season Stats'!$B$3:$B$66,"Isaiah Boyles",'Season Stats'!F$3:F$66)+sumif('Season Stats'!$B$3:$B$66, "Mike Miller",'Season Stats'!F$3:F$66) -> 1 | G23: =sumif('Season Stats'!$B$3:$B$66,"Isaiah Boyles",'Season Stats'!G$3:G$66)+sumif('Season Stats'!$B$3:$B$66, "Mike Miller",'Season Stats'!G$3:G$66) -> 5 | H23: =sumif('Season Stats'!$B$3:$B$66,"Isaiah Boyles",'Season Stats'!H$3:H$66)+sumif('Season Stats'!$B$3:$B$66, "Mike Miller",'Season Stats'!H$3:H$66) -> 0 | I23: =sumif('Season Stats'!$B$3:$B$66,"Isaiah Boyles",'Season Stats'!I$3:I$66)+sumif('Season Stats'!$B$3:$B$66, "Mike Miller",'Season Stats'!I$3:I$66) -> 0 | J23: =sumif('Season Stats'!$B$3:$B$66,"Isaiah Boyles",'Season Stats'!J$3:J$66)+sumif('Season Stats'!$B$3:$B$66, "Mike Miller",'Season Stats'!J$3:J$66) -> 0 | K23: =sumif('Season Stats'!$B$3:$B$66,"Isaiah Boyles",'Season Stats'!K$3:K$66)+sumif('Season Stats'!$B$3:$B$66, "Mike Miller",'Season Stats'!K$3:K$66) -> 0
B24: Bello/Keith | C24: =IFERROR((D24/(D24+E24)),0) -> 0.22222222 | D24: =sumif('Season Stats'!$B$3:$B$66,"Will Bello",'Season Stats'!D$3:D$66)+sumif('Season Stats'!$B$3:$B$66, "Keith Buenrostro",'Season Stats'!D$3:D$66) -> 20 | E24: =sumif('Season Stats'!$B$3:$B$66,"Will Bello",'Season Stats'!E$3:E$66)+sumif('Season Stats'!$B$3:$B$66, "Keith Buenrostro",'Season Stats'!E$3:E$66) -> 70 | F24: =sumif('Season Stats'!$B$3:$B$66,"Will Bello",'Season Stats'!F$3:F$66)+sumif('Season Stats'!$B$3:$B$66, "Keith Buenrostro",'Season Stats'!F$3:F$66) -> 5 | G24: =sumif('Season Stats'!$B$3:$B$66,"Will Bello",'Season Stats'!G$3:G$66)+sumif('Season Stats'!$B$3:$B$66, "Keith Buenrostro",'Season Stats'!G$3:G$66) -> 7 | H24: =sumif('Season Stats'!$B$3:$B$66,"Will Bello",'Season Stats'!H$3:H$66)+sumif('Season Stats'!$B$3:$B$66, "Keith Buenrostro",'Season Stats'!H$3:H$66) -> 0 | I24: =sumif('Season Stats'!$B$3:$B$66,"Will Bello",'Season Stats'!I$3:I$66)+sumif('Season Stats'!$B$3:$B$66, "Keith Buenrostro",'Season Stats'!I$3:I$66) -> 0 | J24: =sumif('Season Stats'!$B$3:$B$66,"Will Bello",'Season Stats'!J$3:J$66)+sumif('Season Stats'!$B$3:$B$66, "Keith Buenrostro",'Season Stats'!J$3:J$66) -> 0 | K24: =sumif('Season Stats'!$B$3:$B$66,"Will Bello",'Season Stats'!K$3:K$66)+sumif('Season Stats'!$B$3:$B$66, "Keith Buenrostro",'Season Stats'!K$3:K$66) -> 0
B25: Arturo/Griss | C25: =IFERROR((D25/(D25+E25)),0) -> 0.21666667 | D25: =sumif('Season Stats'!$B$3:$B$66,"Arturo Martinez",'Season Stats'!D$3:D$66)+sumif('Season Stats'!$B$3:$B$66, "John Grissinger",'Season Stats'!D$3:D$66) -> 26 | E25: =sumif('Season Stats'!$B$3:$B$66,"Arturo Martinez",'Season Stats'!E$3:E$66)+sumif('Season Stats'!$B$3:$B$66, "John Grissinger",'Season Stats'!E$3:E$66) -> 94 | F25: =sumif('Season Stats'!$B$3:$B$66,"Arturo Martinez",'Season Stats'!F$3:F$66)+sumif('Season Stats'!$B$3:$B$66, "John Grissinger",'Season Stats'!F$3:F$66) -> 2 | G25: =sumif('Season Stats'!$B$3:$B$66,"Arturo Martinez",'Season Stats'!G$3:G$66)+sumif('Season Stats'!$B$3:$B$66, "John Grissinger",'Season Stats'!G$3:G$66) -> 8 | H25: =sumif('Season Stats'!$B$3:$B$66,"Arturo Martinez",'Season Stats'!H$3:H$66)+sumif('Season Stats'!$B$3:$B$66, "John Grissinger",'Season Stats'!H$3:H$66) -> 0 | I25: =sumif('Season Stats'!$B$3:$B$66,"Arturo Martinez",'Season Stats'!I$3:I$66)+sumif('Season Stats'!$B$3:$B$66, "John Grissinger",'Season Stats'!I$3:I$66) -> 0 | J25: =sumif('Season Stats'!$B$3:$B$66,"Arturo Martinez",'Season Stats'!J$3:J$66)+sumif('Season Stats'!$B$3:$B$66, "John Grissinger",'Season Stats'!J$3:J$66) -> 0 | K25: =sumif('Season Stats'!$B$3:$B$66,"Arturo Martinez",'Season Stats'!K$3:K$66)+sumif('Season Stats'!$B$3:$B$66, "John Grissinger",'Season Stats'!K$3:K$66) -> 0
B26: Digs/Manndrew | C26: =IFERROR((D26/(D26+E26)),0) -> 0.20689655 | D26: =sumif('Season Stats'!$B$3:$B$66,"Michael Dignazio",'Season Stats'!D$3:D$66)+sumif('Season Stats'!$B$3:$B$66, "Andrew Mann",'Season Stats'!D$3:D$66) -> 6 | E26: =sumif('Season Stats'!$B$3:$B$66,"Michael Dignazio",'Season Stats'!E$3:E$66)+sumif('Season Stats'!$B$3:$B$66, "Andrew Mann",'Season Stats'!E$3:E$66) -> 23 | F26: =sumif('Season Stats'!$B$3:$B$66,"Michael Dignazio",'Season Stats'!F$3:F$66)+sumif('Season Stats'!$B$3:$B$66, "Andrew Mann",'Season Stats'!F$3:F$66) -> 1 | G26: =sumif('Season Stats'!$B$3:$B$66,"Michael Dignazio",'Season Stats'!G$3:G$66)+sumif('Season Stats'!$B$3:$B$66, "Andrew Mann",'Season Stats'!G$3:G$66) -> 2 | H26: =sumif('Season Stats'!$B$3:$B$66,"Michael Dignazio",'Season Stats'!H$3:H$66)+sumif('Season Stats'!$B$3:$B$66, "Andrew Mann",'Season Stats'!H$3:H$66) -> 0 | I26: =sumif('Season Stats'!$B$3:$B$66,"Michael Dignazio",'Season Stats'!I$3:I$66)+sumif('Season Stats'!$B$3:$B$66, "Andrew Mann",'Season Stats'!I$3:I$66) -> 0 | J26: =sumif('Season Stats'!$B$3:$B$66,"Michael Dignazio",'Season Stats'!J$3:J$66)+sumif('Season Stats'!$B$3:$B$66, "Andrew Mann",'Season Stats'!J$3:J$66) -> 0 | K26: =sumif('Season Stats'!$B$3:$B$66,"Michael Dignazio",'Season Stats'!K$3:K$66)+sumif('Season Stats'!$B$3:$B$66, "Andrew Mann",'Season Stats'!K$3:K$66) -> 0
B27: Giacomo/Skatz | C27: =IFERROR((D27/(D27+E27)),0) -> 0.20529801 | D27: =sumif('Season Stats'!$B$3:$B$66,"Giacomo Pugliese",'Season Stats'!D$3:D$66)+sumif('Season Stats'!$B$3:$B$66, "Sammy Katz",'Season Stats'!D$3:D$66) -> 31 | E27: =sumif('Season Stats'!$B$3:$B$66,"Giacomo Pugliese",'Season Stats'!E$3:E$66)+sumif('Season Stats'!$B$3:$B$66, "Sammy Katz",'Season Stats'!E$3:E$66) -> 120 | F27: =sumif('Season Stats'!$B$3:$B$66,"Giacomo Pugliese",'Season Stats'!F$3:F$66)+sumif('Season Stats'!$B$3:$B$66, "Sammy Katz",'Season Stats'!F$3:F$66) -> 4 | G27: =sumif('Season Stats'!$B$3:$B$66,"Giacomo Pugliese",'Season Stats'!G$3:G$66)+sumif('Season Stats'!$B$3:$B$66, "Sammy Katz",'Season Stats'!G$3:G$66) -> 11 | H27: =sumif('Season Stats'!$B$3:$B$66,"Giacomo Pugliese",'Season Stats'!H$3:H$66)+sumif('Season Stats'!$B$3:$B$66, "Sammy Katz",'Season Stats'!H$3:H$66) -> 0 | I27: =sumif('Season Stats'!$B$3:$B$66,"Giacomo Pugliese",'Season Stats'!I$3:I$66)+sumif('Season Stats'!$B$3:$B$66, "Sammy Katz",'Season Stats'!I$3:I$66) -> 0 | J27: =sumif('Season Stats'!$B$3:$B$66,"Giacomo Pugliese",'Season Stats'!J$3:J$66)+sumif('Season Stats'!$B$3:$B$66, "Sammy Katz",'Season Stats'!J$3:J$66) -> 0 | K27: =sumif('Season Stats'!$B$3:$B$66,"Giacomo Pugliese",'Season Stats'!K$3:K$66)+sumif('Season Stats'!$B$3:$B$66, "Sammy Katz",'Season Stats'!K$3:K$66) -> 0
B28: Everett/Hulu | C28: =IFERROR((D28/(D28+E28)),0) -> 0.2027027 | D28: =sumif('Season Stats'!$B$3:$B$66,"Everett Schroeder",'Season Stats'!D$3:D$66)+sumif('Season Stats'!$B$3:$B$66, "Henry Lewis",'Season Stats'!D$3:D$66) -> 30 | E28: =sumif('Season Stats'!$B$3:$B$66,"Everett Schroeder",'Season Stats'!E$3:E$66)+sumif('Season Stats'!$B$3:$B$66, "Henry Lewis",'Season Stats'!E$3:E$66) -> 118 | F28: =sumif('Season Stats'!$B$3:$B$66,"Everett Schroeder",'Season Stats'!F$3:F$66)+sumif('Season Stats'!$B$3:$B$66, "Henry Lewis",'Season Stats'!F$3:F$66) -> 14 | G28: =sumif('Season Stats'!$B$3:$B$66,"Everett Schroeder",'Season Stats'!G$3:G$66)+sumif('Season Stats'!$B$3:$B$66, "Henry Lewis",'Season Stats'!G$3:G$66) -> 4 | H28: =sumif('Season Stats'!$B$3:$B$66,"Everett Schroeder",'Season Stats'!H$3:H$66)+sumif('Season Stats'!$B$3:$B$66, "Henry Lewis",'Season Stats'!H$3:H$66) -> 0 | I28: =sumif('Season Stats'!$B$3:$B$66,"Everett Schroeder",'Season Stats'!I$3:I$66)+sumif('Season Stats'!$B$3:$B$66, "Henry Lewis",'Season Stats'!I$3:I$66) -> 0 | J28: =sumif('Season Stats'!$B$3:$B$66,"Everett Schroeder",'Season Stats'!J$3:J$66)+sumif('Season Stats'!$B$3:$B$66, "Henry Lewis",'Season Stats'!J$3:J$66) -> 0 | K28: =sumif('Season Stats'!$B$3:$B$66,"Everett Schroeder",'Season Stats'!K$3:K$66)+sumif('Season Stats'!$B$3:$B$66, "Henry Lewis",'Season Stats'!K$3:K$66) -> 1
B29: Plump/Voelkbeezy | C29: =IFERROR((D29/(D29+E29)),0) -> 0.2 | D29: =sumif('Season Stats'!$B$3:$B$66,"Andrew Plumpton",'Season Stats'!D$3:D$66)+sumif('Season Stats'!$B$3:$B$66, "Jack Voelker",'Season Stats'!D$3:D$66) -> 13 | E29: =sumif('Season Stats'!$B$3:$B$66,"Andrew Plumpton",'Season Stats'!E$3:E$66)+sumif('Season Stats'!$B$3:$B$66, "Jack Voelker",'Season Stats'!E$3:E$66) -> 52 | F29: =sumif('Season Stats'!$B$3:$B$66,"Andrew Plumpton",'Season Stats'!F$3:F$66)+sumif('Season Stats'!$B$3:$B$66, "Jack Voelker",'Season Stats'!F$3:F$66) -> 3 | G29: =sumif('Season Stats'!$B$3:$B$66,"Andrew Plumpton",'Season Stats'!G$3:G$66)+sumif('Season Stats'!$B$3:$B$66, "Jack Voelker",'Season Stats'!G$3:G$66) -> 2 | H29: =sumif('Season Stats'!$B$3:$B$66,"Andrew Plumpton",'Season Stats'!H$3:H$66)+sumif('Season Stats'!$B$3:$B$66, "Jack Voelker",'Season Stats'!H$3:H$66) -> 1 | I29: =sumif('Season Stats'!$B$3:$B$66,"Andrew Plumpton",'Season Stats'!I$3:I$66)+sumif('Season Stats'!$B$3:$B$66, "Jack Voelker",'Season Stats'!I$3:I$66) -> 0 | J29: =sumif('Season Stats'!$B$3:$B$66,"Andrew Plumpton",'Season Stats'!J$3:J$66)+sumif('Season Stats'!$B$3:$B$66, "Jack Voelker",'Season Stats'!J$3:J$66) -> 0 | K29: =sumif('Season Stats'!$B$3:$B$66,"Andrew Plumpton",'Season Stats'!K$3:K$66)+sumif('Season Stats'!$B$3:$B$66, "Jack Voelker",'Season Stats'!K$3:K$66) -> 0
B30: Reed/Pranav | C30: =IFERROR((D30/(D30+E30)),0) -> 0.18139535 | D30: =sumif('Season Stats'!$B$3:$B$66,"Reed Schoenfeld",'Season Stats'!D$3:D$66)+sumif('Season Stats'!$B$3:$B$66, "Pranav Ravulapati",'Season Stats'!D$3:D$66) -> 39 | E30: =sumif('Season Stats'!$B$3:$B$66,"Reed Schoenfeld",'Season Stats'!E$3:E$66)+sumif('Season Stats'!$B$3:$B$66, "Pranav Ravulapati",'Season Stats'!E$3:E$66) -> 176 | F30: =sumif('Season Stats'!$B$3:$B$66,"Reed Schoenfeld",'Season Stats'!F$3:F$66)+sumif('Season Stats'!$B$3:$B$66, "Pranav Ravulapati",'Season Stats'!F$3:F$66) -> 1 | G30: =sumif('Season Stats'!$B$3:$B$66,"Reed Schoenfeld",'Season Stats'!G$3:G$66)+sumif('Season Stats'!$B$3:$B$66, "Pranav Ravulapati",'Season Stats'!G$3:G$66) -> 16 | H30: =sumif('Season Stats'!$B$3:$B$66,"Reed Schoenfeld",'Season Stats'!H$3:H$66)+sumif('Season Stats'!$B$3:$B$66, "Pranav Ravulapati",'Season Stats'!H$3:H$66) -> 0 | I30: =sumif('Season Stats'!$B$3:$B$66,"Reed Schoenfeld",'Season Stats'!I$3:I$66)+sumif('Season Stats'!$B$3:$B$66, "Pranav Ravulapati",'Season Stats'!I$3:I$66) -> 0 | J30: =sumif('Season Stats'!$B$3:$B$66,"Reed Schoenfeld",'Season Stats'!J$3:J$66)+sumif('Season Stats'!$B$3:$B$66, "Pranav Ravulapati",'Season Stats'!J$3:J$66) -> 0 | K30: =sumif('Season Stats'!$B$3:$B$66,"Reed Schoenfeld",'Season Stats'!K$3:K$66)+sumif('Season Stats'!$B$3:$B$66, "Pranav Ravulapati",'Season Stats'!K$3:K$66) -> 0
B31: Camden/Hamoui | C31: =IFERROR((D31/(D31+E31)),0) -> 0.17721519 | D31: =sumif('Season Stats'!$B$3:$B$66,"Camden Reeves",'Season Stats'!D$3:D$66)+sumif('Season Stats'!$B$3:$B$66, "Gabriel Hamoui",'Season Stats'!D$3:D$66) -> 28 | E31: =sumif('Season Stats'!$B$3:$B$66,"Camden Reeves",'Season Stats'!E$3:E$66)+sumif('Season Stats'!$B$3:$B$66, "Gabriel Hamoui",'Season Stats'!E$3:E$66) -> 130 | F31: =sumif('Season Stats'!$B$3:$B$66,"Camden Reeves",'Season Stats'!F$3:F$66)+sumif('Season Stats'!$B$3:$B$66, "Gabriel Hamoui",'Season Stats'!F$3:F$66) -> 6 | G31: =sumif('Season Stats'!$B$3:$B$66,"Camden Reeves",'Season Stats'!G$3:G$66)+sumif('Season Stats'!$B$3:$B$66, "Gabriel Hamoui",'Season Stats'!G$3:G$66) -> 7 | H31: =sumif('Season Stats'!$B$3:$B$66,"Camden Reeves",'Season Stats'!H$3:H$66)+sumif('Season Stats'!$B$3:$B$66, "Gabriel Hamoui",'Season Stats'!H$3:H$66) -> 2 | I31: =sumif('Season Stats'!$B$3:$B$66,"Camden Reeves",'Season Stats'!I$3:I$66)+sumif('Season Stats'!$B$3:$B$66, "Gabriel Hamoui",'Season Stats'!I$3:I$66) -> 0 | J31: =sumif('Season Stats'!$B$3:$B$66,"Camden Reeves",'Season Stats'!J$3:J$66)+sumif('Season Stats'!$B$3:$B$66, "Gabriel Hamoui",'Season Stats'!J$3:J$66) -> 0 | K31: =sumif('Season Stats'!$B$3:$B$66,"Camden Reeves",'Season Stats'!K$3:K$66)+sumif('Season Stats'!$B$3:$B$66, "Gabriel Hamoui",'Season Stats'!K$3:K$66) -> 0
B32: Bash/Grant Mullen | C32: =IFERROR((D32/(D32+E32)),0) -> 0.17 | D32: =sumif('Season Stats'!$B$3:$B$66,"Zach Bashour",'Season Stats'!D$3:D$66)+sumif('Season Stats'!$B$3:$B$66, "Grant Mullen",'Season Stats'!D$3:D$66) -> 34 | E32: =sumif('Season Stats'!$B$3:$B$66,"Zach Bashour",'Season Stats'!E$3:E$66)+sumif('Season Stats'!$B$3:$B$66, "Grant Mullen",'Season Stats'!E$3:E$66) -> 166 | F32: =sumif('Season Stats'!$B$3:$B$66,"Zach Bashour",'Season Stats'!F$3:F$66)+sumif('Season Stats'!$B$3:$B$66, "Grant Mullen",'Season Stats'!F$3:F$66) -> 1 | G32: =sumif('Season Stats'!$B$3:$B$66,"Zach Bashour",'Season Stats'!G$3:G$66)+sumif('Season Stats'!$B$3:$B$66, "Grant Mullen",'Season Stats'!G$3:G$66) -> 11 | H32: =sumif('Season Stats'!$B$3:$B$66,"Zach Bashour",'Season Stats'!H$3:H$66)+sumif('Season Stats'!$B$3:$B$66, "Grant Mullen",'Season Stats'!H$3:H$66) -> 0 | I32: =sumif('Season Stats'!$B$3:$B$66,"Zach Bashour",'Season Stats'!I$3:I$66)+sumif('Season Stats'!$B$3:$B$66, "Grant Mullen",'Season Stats'!I$3:I$66) -> 0 | J32: =sumif('Season Stats'!$B$3:$B$66,"Zach Bashour",'Season Stats'!J$3:J$66)+sumif('Season Stats'!$B$3:$B$66, "Grant Mullen",'Season Stats'!J$3:J$66) -> 0 | K32: =sumif('Season Stats'!$B$3:$B$66,"Zach Bashour",'Season Stats'!K$3:K$66)+sumif('Season Stats'!$B$3:$B$66, "Grant Mullen",'Season Stats'!K$3:K$66) -> 0
B33: PJ/Chris Connors | C33: =IFERROR((D33/(D33+E33)),0) -> 0.16901408 | D33: =sumif('Season Stats'!$B$3:$B$66,"PJ Ogilvie",'Season Stats'!D$3:D$66)+sumif('Season Stats'!$B$3:$B$66, "Chris Connors",'Season Stats'!D$3:D$66) -> 12 | E33: =sumif('Season Stats'!$B$3:$B$66,"PJ Ogilvie",'Season Stats'!E$3:E$66)+sumif('Season Stats'!$B$3:$B$66, "Chris Connors",'Season Stats'!E$3:E$66) -> 59 | F33: =sumif('Season Stats'!$B$3:$B$66,"PJ Ogilvie",'Season Stats'!F$3:F$66)+sumif('Season Stats'!$B$3:$B$66, "Chris Connors",'Season Stats'!F$3:F$66) -> 3 | G33: =sumif('Season Stats'!$B$3:$B$66,"PJ Ogilvie",'Season Stats'!G$3:G$66)+sumif('Season Stats'!$B$3:$B$66, "Chris Connors",'Season Stats'!G$3:G$66) -> 2 | H33: =sumif('Season Stats'!$B$3:$B$66,"PJ Ogilvie",'Season Stats'!H$3:H$66)+sumif('Season Stats'!$B$3:$B$66, "Chris Connors",'Season Stats'!H$3:H$66) -> 1 | I33: =sumif('Season Stats'!$B$3:$B$66,"PJ Ogilvie",'Season Stats'!I$3:I$66)+sumif('Season Stats'!$B$3:$B$66, "Chris Connors",'Season Stats'!I$3:I$66) -> 0 | J33: =sumif('Season Stats'!$B$3:$B$66,"PJ Ogilvie",'Season Stats'!J$3:J$66)+sumif('Season Stats'!$B$3:$B$66, "Chris Connors",'Season Stats'!J$3:J$66) -> 0 | K33: =sumif('Season Stats'!$B$3:$B$66,"PJ Ogilvie",'Season Stats'!K$3:K$66)+sumif('Season Stats'!$B$3:$B$66, "Chris Connors",'Season Stats'!K$3:K$66) -> 0
B34: Curtis/Ronilo | C34: =IFERROR((D34/(D34+E34)),0) -> 0.16528926 | D34: =sumif('Season Stats'!$B$3:$B$66,"Ben Curtis",'Season Stats'!D$3:D$66)+sumif('Season Stats'!$B$3:$B$66, "Jack Ronilo",'Season Stats'!D$3:D$66) -> 20 | E34: =sumif('Season Stats'!$B$3:$B$66,"Ben Curtis",'Season Stats'!E$3:E$66)+sumif('Season Stats'!$B$3:$B$66, "Jack Ronilo",'Season Stats'!E$3:E$66) -> 101 | F34: =sumif('Season Stats'!$B$3:$B$66,"Ben Curtis",'Season Stats'!F$3:F$66)+sumif('Season Stats'!$B$3:$B$66, "Jack Ronilo",'Season Stats'!F$3:F$66) -> 3 | G34: =sumif('Season Stats'!$B$3:$B$66,"Ben Curtis",'Season Stats'!G$3:G$66)+sumif('Season Stats'!$B$3:$B$66, "Jack Ronilo",'Season Stats'!G$3:G$66) -> 8 | H34: =sumif('Season Stats'!$B$3:$B$66,"Ben Curtis",'Season Stats'!H$3:H$66)+sumif('Season Stats'!$B$3:$B$66, "Jack Ronilo",'Season Stats'!H$3:H$66) -> 1 | I34: =sumif('Season Stats'!$B$3:$B$66,"Ben Curtis",'Season Stats'!I$3:I$66)+sumif('Season Stats'!$B$3:$B$66, "Jack Ronilo",'Season Stats'!I$3:I$66) -> 0 | J34: =sumif('Season Stats'!$B$3:$B$66,"Ben Curtis",'Season Stats'!J$3:J$66)+sumif('Season Stats'!$B$3:$B$66, "Jack Ronilo",'Season Stats'!J$3:J$66) -> 0 | K34: =sumif('Season Stats'!$B$3:$B$66,"Ben Curtis",'Season Stats'!K$3:K$66)+sumif('Season Stats'!$B$3:$B$66, "Jack Ronilo",'Season Stats'!K$3:K$66) -> 0

Sheet Playoff Stats
B2: Shooter | C2: Shooting | D2: Cups Made | E2: Cups Missed | F2: Splash-Out | G2: Guy | H2: Tri | I2: Di | J2: Un | K2: Vom
B3: Jack Wigmore | C3: =IFERROR((D3/(D3+E3)),0) -> 0.33333333 | D3: =6+6 -> 12 | E3: =11+13 -> 24 | F3: 1 | G3: 2 | H3: 0 | I3: 0 | J3: 0 | K3: 0
B4: Heath Lawry | C4: =IFERROR((D4/(D4+E4)),0) -> 0.33333333 | D4: =6+5 -> 11 | E4: =6+16 -> 22 | F4: 1 | G4: 2 | H4: 0 | I4: 0 | J4: 0 | K4: 0
B5: Takoa Cartwright | C5: =IFERROR((D5/(D5+E5)),0) -> 0.32432432 | D5: =7+5 -> 12 | E5: =11+14 -> 25 | F5: 2 | G5: =1+1 -> 2 | H5: 0 | I5: 0 | J5: 0 | K5: 0
B6: Joe Raza | C6: =IFERROR((D6/(D6+E6)),0) -> 0.3125 | D6: 5 | E6: 11 | F6: 1 | G6: 2 | H6: 1 | I6: 0 | J6: 0 | K6: 0
B7: Hudson Stolz | C7: =IFERROR((D7/(D7+E7)),0) -> 0.31034483 | D7: =6+3 -> 9 | E7: =9+11 -> 20 | F7: 2 | G7: 1 | H7: 0 | I7: 0 | J7: 0 | K7: 0
B8: Liam Byrne | C8: =IFERROR((D8/(D8+E8)),0) -> 0.29411765 | D8: 5 | E8: 12 | F8: 2 | G8: 0 | H8: 0 | I8: 0 | J8: 0 | K8: 0
B9: Brock Benton | C9: =IFERROR((D9/(D9+E9)),0) -> 0.29411765 | D9: 5 | E9: 12 | F9: 1 | G9: 0 | H9: 0 | I9: 0 | J9: 0 | K9: 0
B10: Charlie Truesdale | C10: =IFERROR((D10/(D10+E10)),0) -> 0.27777778 | D10: 5 | E10: 13 | F10: 1 | G10: 0 | H10: 0 | I10: 0 | J10: 0 | K10: 0
B11: Anson Mies | C11: =IFERROR((D11/(D11+E11)),0) -> 0.27027027 | D11: =6+4 -> 10 | E11: =15+12 -> 27 | F11: 2 | G11: =1+1 -> 2 | H11: 0 | I11: 0 | J11: 0 | K11: 0
B12: Will Creamer | C12: =IFERROR((D12/(D12+E12)),0) -> 0.26666667 | D12: =4+4 -> 8 | E12: =12+10 -> 22 | F12: 1 | G12: =1+1 -> 2 | H12: 1 | I12: 0 | J12: 0 | K12: 0
B13: John Tolsma | C13: =IFERROR((D13/(D13+E13)),0) -> 0.26666667 | D13: 4 | E13: 11 | F13: 1 | G13: 0 | H13: 0 | I13: 0 | J13: 0 | K13: 0
B14: Luke Brandon | C14: =IFERROR((D14/(D14+E14)),0) -> 0.24242424 | D14: =4+4 -> 8 | E14: =8+17 -> 25 | F14: 3 | G14: 0 | H14: 0 | I14: 0 | J14: 0 | K14: 0
B15: Charlie Boggs | C15: =IFERROR((D15/(D15+E15)),0) -> 0.23529412 | D15: =4+4 -> 8 | E15: =12+14 -> 26 | F15: 2 | G15: 1 | H15: 0 | I15: 0 | J15: 0 | K15: 0
B16: Ford Tate | C16: =IFERROR((D16/(D16+E16)),0) -> 0.225 | D16: =5+4 -> 9 | E16: =13+18 -> 31 | F16: 0 | G16: 1 | H16: 0 | I16: 0 | J16: 0 | K16: 1
B17: Henry Lewis | C17: =IFERROR((D17/(D17+E17)),0) -> 0.22222222 | D17: =5+7 -> 12 | E17: =25+17 -> 42 | F17: =8+1 -> 9 | G17: =1+2 -> 3 | H17: 0 | I17: 0 | J17: 0 | K17: 0
B18: Jaden Pearlmutter | C18: =IFERROR((D18/(D18+E18)),0) -> 0.2195122 | D18: =5+4 -> 9 | E18: =13+19 -> 32 | F18: =1+3 -> 4 | G18: 0 | H18: 0 | I18: 0 | J18: 0 | K18: 0
B19: Pierre Gathy | C19: =IFERROR((D19/(D19+E19)),0) -> 0.21621622 | D19: =4+4 -> 8 | E19: =17+12 -> 29 | F19: 2 | G19: 0 | H19: 0 | I19: 0 | J19: 0 | K19: 0
B20: Mati Gandarias | C20: =IFERROR((D20/(D20+E20)),0) -> 0.21621622 | D20: =3+5 -> 8 | E20: =15+14 -> 29 | F20: 2 | G20: 1 | H20: 0 | I20: 0 | J20: 0 | K20: 0
B21: Emilio Garcia | C21: =IFERROR((D21/(D21+E21)),0) -> 0.21428571 | D21: 3 | E21: 11 | F21: 0 | G21: 1 | H21: 0 | I21: 0 | J21: 0 | K21: 0
B22: Toban Doody | C22: =IFERROR((D22/(D22+E22)),0) -> 0.20689655 | D22: 6 | E22: 23 | F22: 1 | G22: 3 | H22: 0 | I22: 0 | J22: 0 | K22: 0
B23: Grant Mullen | C23: =IFERROR((D23/(D23+E23)),0) -> 0.19047619 | D23: 4 | E23: 17 | F23: 1 | G23: 0 | H23: 0 | I23: 0 | J23: 0 | K23: 0
B24: Vinny Drolet | C24: =IFERROR((D24/(D24+E24)),0) -> 0.1875 | D24: 3 | E24: 13 | F24: 0 | G24: 0 | H24: 0 | I24: 0 | J24: 0 | K24: 0
B25: Reed Schoenfeld | C25: =IFERROR((D25/(D25+E25)),0) -> 0.17857143 | D25: 5 | E25: 23 | F25: 0 | G25: 1 | H25: 0 | I25: 0 | J25: 0 | K25: 0
B26: Naman Kulkarni | C26: =IFERROR((D26/(D26+E26)),0) -> 0.17647059 | D26: 3 | E26: 14 | F26: 1 | G26: 3 | H26: 0 | I26: 0 | J26: 0 | K26: 0
B27: Gabriel Hamoui | C27: =IFERROR((D27/(D27+E27)),0) -> 0.17391304 | D27: =5+3 -> 8 | E27: =22+16 -> 38 | F27: 2 | G27: =1+1 -> 2 | H27: =1+1 -> 2 | I27: 0 | J27: 0 | K27: 0
B28: Evan Sarchio | C28: =IFERROR((D28/(D28+E28)),0) -> 0.16666667 | D28: 3 | E28: 15 | F28: 0 | G28: 0 | H28: 0 | I28: 0 | J28: 0 | K28: 0
B29: Pranav Ravulapati | C29: =IFERROR((D29/(D29+E29)),0) -> 0.14814815 | D29: 4 | E29: 23 | F29: 0 | G29: 2 | H29: 0 | I29: 0 | J29: 0 | K29: 0
B30: Everett Schroeder | C30: =IFERROR((D30/(D30+E30)),0) -> 0.14814815 | D30: =5+3 -> 8 | E30: =25+21 -> 46 | F30: 2 | G30: =2+5 -> 7 | H30: 0 | I30: 0 | J30: 0 | K30: 0
B31: Henry Morrison | C31: =IFERROR((D31/(D31+E31)),0) -> 0.10344828 | D31: 3 | E31: 26 | F31: 1 | G31: 3 | H31: 0 | I31: 0 | J31: 0 | K31: 0
B32: Camden Reeves | C32: =IFERROR((D32/(D32+E32)),0) -> 0.088888889 | D32: =2+2 -> 4 | E32: =24+17 -> 41 | F32: =1 -> 1 | G32: =1+1 -> 2 | H32: 0 | I32: 0 | J32: 0 | K32: 0
B33: Gabriel Blumenschein | C33: =IFERROR((D33/(D33+E33)),0) -> 0.0625 | D33: 1 | E33: 15 | F33: 0 | G33: 1 | H33: 0 | I33: 0 | J33: 0 | K33: 0
B34: Zach Bashour | C34: =IFERROR((D34/(D34+E34)),0) -> 0.047619048 | D34: 1 | E34: 20 | F34: 0 | G34: 2 | H34: 0 | I34: 0 | J34: 0 | K34: 0

Sheet Playoff Bracket (16)
B1: Sweet 16 | E1: Elite 8 | H1: Final 4 | K1: Championship | M1: =H1 -> Final 4 | P1: =E1 -> Elite 8 | S1: =B1 -> Sweet 16
B3: TRUE | C3: (1) Brando/Heath | S3: (6) Chuckdee/Sarch | T3: FALSE
B4: FALSE | C4: (16) Tolsma/Emilio | J4: Champion | S4: (11) Ford/JP | T4: TRUE
J5: {=iferror(vlookup(TRUE,J10:K10,2,False),iferror(VLOOKUP(TRUE,{$L$11,$K$11},2,FALSE), " "))} -> (3) Ev/Hulu
B6: Hott Region | S6: Carteaux Region
E7: FALSE | F7: =iferror(vlookup(TRUE,B3:C4,2,False),"") -> (1) Brando/Heath | P7: {=iferror(VLOOKUP(TRUE,{$T$3:$T$4,$S$3:$S$4},2,FALSE),"")} -> (11) Ford/JP | Q7: FALSE
E8: TRUE | F8: =iferror(vlookup(TRUE,B11:C12,2,False),"") -> (9) Mati/Takoa | P8: {=iferror(VLOOKUP(TRUE,{$T$11:$T$12,$S$11:$S$12},2,FALSE),"")} -> (3) Ev/Hulu | Q8: TRUE
J10: FALSE | K10: =iferror(vlookup(TRUE,H13:I14,2,False),"") -> (4) Wigs/Boggs
B11: FALSE | C11: (8) Blume/Raza | K11: {=iferror(VLOOKUP(TRUE,{$N$13:$N$14,$M$13:$M$14},2,FALSE),"")} -> (3) Ev/Hulu | L11: TRUE | S11: (3) Ev/Hulu | T11: TRUE
B12: TRUE | C12: (9) Mati/Takoa | S12: (14) Toban/Homo | T12: FALSE
H13: FALSE | I13: =iferror(vlookup(TRUE,E7:F8,2,False),"") -> (9) Mati/Takoa | M13: {=iferror(VLOOKUP(TRUE,{$Q$7:$Q$8,$P$7:$P$8},2,FALSE),"")} -> (3) Ev/Hulu | N13: TRUE
H14: TRUE | I14: =iferror(vlookup(TRUE,E19:F20,2,False),"") -> (4) Wigs/Boggs | M14: {=iferror(VLOOKUP(TRUE,{$Q$19:$Q$20,$P$19:$P$20},2,FALSE),"")} -> (7) Creamer/Hudson | N14: FALSE
B15: FALSE | C15: (5) Pranav/Reed | S15: (7) Creamer/Hudson | T15: TRUE
B16: TRUE | C16: (12) Cam/Ham | S16: (10) Brock/Vinny | T16: FALSE
B18: Pruitt Region | S18: Aldridge Region
